Workbook

Sheet Raw Data
B2: RIO US EQUITY | F2: ISIX62IU Index | J2: HG1 Comdty | N2: LMAHDS03 Comdty | R2: AUDUSD Curncy | V2: SPX Index | Z2: CHMMCRST Index | AD2: 9246R005 Index | AH2: NAPMPMI Index
A3: =EOMONTH(B3,0) -> 40268 | B3: 40268 | C3: 59.1825 | E3: =EOMONTH(F3,0) -> 40908 | F3: 40908 | G3: 138.2 | I3: =EOMONTH(J3,0) -> 40268 | J3: 40268 | K3: 355.35 | M3: =EOMONTH(N3,0) -> 40268 | N3: 40268 | O3: 2323 | Q3: =EOMONTH(R3,0) -> 40268 | R3: 40268 | S3: 0.9172 | U3: =EOMONTH(V3,0) -> 40268 | V3: 40268 | W3: 1169.43 | Y3: =EOMONTH(Z3,0) -> 40268 | Z3: 40268 | AA3: 54.97 | AC3: =EOMONTH(AD3,0) -> 40268 | AD3: 40268 | AE3: 95.8 | AG3: =EOMONTH(AH3,0) -> 40633 | AH3: 40633 | AI3: 58.4
A4: =EOMONTH(B4,0) -> 40298 | B4: 40298 | C4: 50.86 | E4: =EOMONTH(F4,0) -> 40939 | F4: 40939 | G4: 141.8 | I4: =EOMONTH(J4,0) -> 40298 | J4: 40298 | K4: 333.75 | M4: =EOMONTH(N4,0) -> 40298 | N4: 40298 | O4: 2255 | Q4: =EOMONTH(R4,0) -> 40298 | R4: 40298 | S4: 0.9243 | U4: =EOMONTH(V4,0) -> 40298 | V4: 40298 | W4: 1186.69 | Y4: =EOMONTH(Z4,0) -> 40298 | Z4: 40298 | AA4: 55.4 | AC4: =EOMONTH(AD4,0) -> 40298 | AD4: 40298 | AE4: 90.8 | AG4: =EOMONTH(AH4,0) -> 40663 | AH4: 40663 | AI4: 57.9
A5: =EOMONTH(B5,0) -> 40329 | B5: 40329 | C5: 46.1 | E5: =EOMONTH(F5,0) -> 40968 | F5: 40968 | G5: 141.4 | I5: =EOMONTH(J5,0) -> 40329 | J5: 40329 | K5: 310.45 | M5: =EOMONTH(N5,0) -> 40329 | N5: 40329 | O5: 2043 | Q5: =EOMONTH(R5,0) -> 40329 | R5: 40329 | S5: 0.8459 | U5: =EOMONTH(V5,0) -> 40329 | V5: 40329 | W5: 1089.41 | Y5: =EOMONTH(Z5,0) -> 40329 | Z5: 40329 | AA5: 56.14 | AC5: =EOMONTH(AD5,0) -> 40329 | AD5: 40329 | AE5: 95.7 | AG5: =EOMONTH(AH5,0) -> 40694 | AH5: 40694 | AI5: 54.8
A6: =EOMONTH(B6,0) -> 40359 | B6: 40359 | C6: 43.6 | E6: =EOMONTH(F6,0) -> 40999 | F6: 40999 | G6: 145.1 | I6: =EOMONTH(J6,0) -> 40359 | J6: 40359 | K6: 293.6 | M6: =EOMONTH(N6,0) -> 40359 | N6: 40359 | O6: 1977.5 | Q6: =EOMONTH(R6,0) -> 40359 | R6: 40359 | S6: 0.8408 | U6: =EOMONTH(V6,0) -> 40359 | V6: 40359 | W6: 1030.71 | Y6: =EOMONTH(Z6,0) -> 40359 | Z6: 40359 | AA6: 53.77 | AC6: =EOMONTH(AD6,0) -> 40359 | AD6: 40359 | AE6: 109 | AG6: =EOMONTH(AH6,0) -> 40724 | AH6: 40724 | AI6: 55.8
A7: =EOMONTH(B7,0) -> 40390 | B7: 40389 | C7: 51.92 | E7: =EOMONTH(F7,0) -> 41029 | F7: 41029 | G7: 145.1 | I7: =EOMONTH(J7,0) -> 40390 | J7: 40389 | K7: 331.15 | M7: =EOMONTH(N7,0) -> 40390 | N7: 40389 | O7: 2175 | Q7: =EOMONTH(R7,0) -> 40390 | R7: 40389 | S7: 0.9042 | U7: =EOMONTH(V7,0) -> 40390 | V7: 40389 | W7: 1101.6 | Y7: =EOMONTH(Z7,0) -> 40390 | Z7: 40390 | AA7: 51.74 | AC7: =EOMONTH(AD7,0) -> 40390 | AD7: 40390 | AE7: 99.9 | AG7: =EOMONTH(AH7,0) -> 40755 | AH7: 40755 | AI7: 52.9
A8: =EOMONTH(B8,0) -> 40421 | B8: 40421 | C8: 50.8606 | E8: =EOMONTH(F8,0) -> 41060 | F8: 41060 | G8: 131.8 | I8: =EOMONTH(J8,0) -> 40421 | J8: 40421 | K8: 336.1 | M8: =EOMONTH(N8,0) -> 40421 | N8: 40421 | O8: 2058 | Q8: =EOMONTH(R8,0) -> 40421 | R8: 40421 | S8: 0.8906 | U8: =EOMONTH(V8,0) -> 40421 | V8: 40421 | W8: 1049.33 | Y8: =EOMONTH(Z8,0) -> 40421 | Z8: 40421 | AA8: 51.64 | AC8: =EOMONTH(AD8,0) -> 40421 | AD8: 40421 | AE8: 101.4 | AG8: =EOMONTH(AH8,0) -> 40786 | AH8: 40786 | AI8: 52.6
A9: =EOMONTH(B9,0) -> 40451 | B9: 40451 | C9: 59.2314 | E9: =EOMONTH(F9,0) -> 41090 | F9: 41090 | G9: 135.1 | I9: =EOMONTH(J9,0) -> 40451 | J9: 40451 | K9: 365.15 | M9: =EOMONTH(N9,0) -> 40451 | N9: 40451 | O9: 2351 | Q9: =EOMONTH(R9,0) -> 40451 | R9: 40451 | S9: 0.9671 | U9: =EOMONTH(V9,0) -> 40451 | V9: 40451 | W9: 1141.2 | Y9: =EOMONTH(Z9,0) -> 40451 | Z9: 40451 | AA9: 47.95 | AC9: =EOMONTH(AD9,0) -> 40451 | AD9: 40451 | AE9: 108.9 | AG9: =EOMONTH(AH9,0) -> 40816 | AH9: 40816 | AI9: 53.7
A10: =EOMONTH(B10,0) -> 40482 | B10: 40480 | C10: 65.676 | E10: =EOMONTH(F10,0) -> 41121 | F10: 41121 | G10: 119.2 | I10: =EOMONTH(J10,0) -> 40482 | J10: 40480 | K10: 373.35 | M10: =EOMONTH(N10,0) -> 40482 | N10: 40480 | O10: 2344 | Q10: =EOMONTH(R10,0) -> 40482 | R10: 40480 | S10: 0.9835 | U10: =EOMONTH(V10,0) -> 40482 | V10: 40480 | W10: 1183.26 | Y10: =EOMONTH(Z10,0) -> 40482 | Z10: 40482 | AA10: 50.3 | AC10: =EOMONTH(AD10,0) -> 40482 | AD10: 40482 | AE10: 106 | AG10: =EOMONTH(AH10,0) -> 40847 | AH10: 40847 | AI10: 51.4
A11: =EOMONTH(B11,0) -> 40512 | B11: 40512 | C11: 64.6775 | E11: =EOMONTH(F11,0) -> 41152 | F11: 41152 | G11: 89.8 | I11: =EOMONTH(J11,0) -> 40512 | J11: 40512 | K11: 382.3 | M11: =EOMONTH(N11,0) -> 40512 | N11: 40512 | O11: 2275 | Q11: =EOMONTH(R11,0) -> 40512 | R11: 40512 | S11: 0.9588 | U11: =EOMONTH(V11,0) -> 40512 | V11: 40512 | W11: 1180.55 | Y11: =EOMONTH(Z11,0) -> 40512 | Z11: 40512 | AA11: 50.17 | AC11: =EOMONTH(AD11,0) -> 40512 | AD11: 40512 | AE11: 110.8 | AG11: =EOMONTH(AH11,0) -> 40877 | AH11: 40877 | AI11: 51.8
A12: =EOMONTH(B12,0) -> 40543 | B12: 40543 | C12: 72.2718 | E12: =EOMONTH(F12,0) -> 41182 | F12: 41182 | G12: 106 | I12: =EOMONTH(J12,0) -> 40543 | J12: 40543 | K12: 444.7 | M12: =EOMONTH(N12,0) -> 40543 | N12: 40543 | O12: 2470 | Q12: =EOMONTH(R12,0) -> 40543 | R12: 40543 | S12: 1.0233 | U12: =EOMONTH(V12,0) -> 40543 | V12: 40543 | W12: 1257.64 | Y12: =EOMONTH(Z12,0) -> 40543 | Z12: 40543 | AA12: 51.52 | AC12: =EOMONTH(AD12,0) -> 40543 | AD12: 40543 | AE12: 118.6 | AG12: =EOMONTH(AH12,0) -> 40908 | AH12: 40908 | AI12: 53
A13: =EOMONTH(B13,0) -> 40574 | B13: 40574 | C13: 70.0732 | E13: =EOMONTH(F13,0) -> 41213 | F13: 41213 | G13: 119.3 | I13: =EOMONTH(J13,0) -> 40574 | J13: 40574 | K13: 445.85 | M13: =EOMONTH(N13,0) -> 40574 | N13: 40574 | O13: 2520 | Q13: =EOMONTH(R13,0) -> 40574 | R13: 40574 | S13: 0.9974 | U13: =EOMONTH(V13,0) -> 40574 | V13: 40574 | W13: 1286.12 | Y13: =EOMONTH(Z13,0) -> 40602 | Z13: 40602 | AA13: 54.31 | AC13: =EOMONTH(AD13,0) -> 40574 | AD13: 40574 | AE13: 98.8 | AG13: =EOMONTH(AH13,0) -> 40939 | AH13: 40939 | AI13: 54.2
A14: =EOMONTH(B14,0) -> 40602 | B14: 40602 | C14: 71.6869 | E14: =EOMONTH(F14,0) -> 41243 | F14: 41243 | G14: 116.7 | I14: =EOMONTH(J14,0) -> 40602 | J14: 40602 | K14: 447.8 | M14: =EOMONTH(N14,0) -> 40602 | N14: 40602 | O14: 2600 | Q14: =EOMONTH(R14,0) -> 40602 | R14: 40602 | S14: 1.0186 | U14: =EOMONTH(V14,0) -> 40602 | V14: 40602 | W14: 1327.22 | Y14: =EOMONTH(Z14,0) -> 40633 | Z14: 40633 | AA14: 59.42 | AC14: =EOMONTH(AD14,0) -> 40602 | AD14: 40602 | AE14: 85.1 | AG14: =EOMONTH(AH14,0) -> 40968 | AH14: 40968 | AI14: 53.3
... A155: =EOMONTH(B155,0) -> 44895 | B155: 44895 | C155: 146.091 | E155: =EOMONTH(F155,0) -> 45535 | F155: 45535 | G155: 94.89 | I155: =EOMONTH(J155,0) -> 44895 | J155: 44895 | K155: 372.95 | M155: =EOMONTH(N155,0) -> 44895 | N155: 44895 | O155: 2477.5 | Q155: =EOMONTH(R155,0) -> 44895 | R155: 44895 | S155: 0.6788 | U155: =EOMONTH(V155,0) -> 44895 | V155: 44895 | W155: 4080.11 | Y155: =EOMONTH(Z155,0) -> 45747 | Z155: 45747 | AA155: 92.84 | AC155: =EOMONTH(AD155,0) -> 44895 | AD155: 44895 | AE155: 268.4 | AG155: =EOMONTH(AH155,0) -> 45260 | AH155: 45260 | AI155: 46.8
A156: =EOMONTH(B156,0) -> 44926 | B156: 44925 | C156: 151.5396 | E156: =EOMONTH(F156,0) -> 45565 | F156: 45565 | G156: 103.02 | I156: =EOMONTH(J156,0) -> 44926 | J156: 44925 | K156: 381.05 | M156: =EOMONTH(N156,0) -> 44926 | N156: 44925 | O156: 2378 | Q156: =EOMONTH(R156,0) -> 44926 | R156: 44925 | S156: 0.6813 | U156: =EOMONTH(V156,0) -> 44926 | V156: 44925 | W156: 3839.5 | Y156: =EOMONTH(Z156,0) -> 45777 | Z156: 45777 | AA156: 86.02 | AG156: =EOMONTH(AH156,0) -> 45291 | AH156: 45291 | AI156: 46.9
A157: =EOMONTH(B157,0) -> 44957 | B157: 44957 | C157: 168.8857 | E157: =EOMONTH(F157,0) -> 45596 | F157: 45596 | G157: 96.49 | I157: =EOMONTH(J157,0) -> 44957 | J157: 44957 | K157: 422.6 | M157: =EOMONTH(N157,0) -> 44957 | N157: 44957 | O157: 2644 | Q157: =EOMONTH(R157,0) -> 44957 | R157: 44957 | S157: 0.7055 | U157: =EOMONTH(V157,0) -> 44957 | V157: 44957 | W157: 4076.6 | Y157: =EOMONTH(Z157,0) -> 45808 | Z157: 45808 | AA157: 86.55 | AG157: =EOMONTH(AH157,0) -> 45322 | AH157: 45322 | AI157: 48.6
A158: =EOMONTH(B158,0) -> 44985 | B158: 44985 | C158: 148.4109 | E158: =EOMONTH(F158,0) -> 45626 | F158: 45626 | G158: 97.26 | I158: =EOMONTH(J158,0) -> 44985 | J158: 44985 | K158: 409.75 | M158: =EOMONTH(N158,0) -> 44985 | N158: 44985 | O158: 2373 | Q158: =EOMONTH(R158,0) -> 44985 | R158: 44985 | S158: 0.6729 | U158: =EOMONTH(V158,0) -> 44985 | V158: 44985 | W158: 3970.15 | Y158: =EOMONTH(Z158,0) -> 45838 | Z158: 45838 | AA158: 83.18 | AG158: =EOMONTH(AH158,0) -> 45351 | AH158: 45351 | AI158: 47.4
A159: =EOMONTH(B159,0) -> 45016 | B159: 45016 | C159: 150.8213 | E159: =EOMONTH(F159,0) -> 45657 | F159: 45657 | G159: 95.35 | I159: =EOMONTH(J159,0) -> 45016 | J159: 45016 | K159: 409.45 | M159: =EOMONTH(N159,0) -> 45016 | N159: 45016 | O159: 2413 | Q159: =EOMONTH(R159,0) -> 45016 | R159: 45016 | S159: 0.6685 | U159: =EOMONTH(V159,0) -> 45016 | V159: 45016 | W159: 4109.31 | Y159: =EOMONTH(Z159,0) -> 45869 | Z159: 45869 | AA159: 79.66 | AG159: =EOMONTH(AH159,0) -> 45382 | AH159: 45382 | AI159: 49.8
A160: =EOMONTH(B160,0) -> 45046 | B160: 45044 | C160: 140.6859 | E160: =EOMONTH(F160,0) -> 45688 | F160: 45688 | G160: 99.97 | I160: =EOMONTH(J160,0) -> 45046 | J160: 45044 | K160: 387 | M160: =EOMONTH(N160,0) -> 45046 | N160: 45044 | O160: 2356 | Q160: =EOMONTH(R160,0) -> 45046 | R160: 45044 | S160: 0.6615 | U160: =EOMONTH(V160,0) -> 45046 | V160: 45044 | W160: 4169.48 | Y160: =EOMONTH(Z160,0) -> 45900 | Z160: 45900 | AA160: 77.37 | AG160: =EOMONTH(AH160,0) -> 45412 | AH160: 45412 | AI160: 48.9
A161: =EOMONTH(B161,0) -> 45077 | B161: 45077 | C161: 129.825 | E161: =EOMONTH(F161,0) -> 45716 | F161: 45716 | G161: 98.5 | I161: =EOMONTH(J161,0) -> 45077 | J161: 45077 | K161: 363.7 | M161: =EOMONTH(N161,0) -> 45077 | N161: 45077 | O161: 2246 | Q161: =EOMONTH(R161,0) -> 45077 | R161: 45077 | S161: 0.6503 | U161: =EOMONTH(V161,0) -> 45077 | V161: 45077 | W161: 4179.83 | Y161: =EOMONTH(Z161,0) -> 45930 | Z161: 45930 | AA161: 73.49 | AG161: =EOMONTH(AH161,0) -> 45443 | AH161: 45443 | AI161: 48.6
A162: =EOMONTH(B162,0) -> 45107 | B162: 45107 | C162: 140.3562 | E162: =EOMONTH(F162,0) -> 45747 | F162: 45747 | G162: 95.41 | I162: =EOMONTH(J162,0) -> 45107 | J162: 45107 | K162: 374.1 | M162: =EOMONTH(N162,0) -> 45107 | N162: 45107 | O162: 2151.5 | Q162: =EOMONTH(R162,0) -> 45107 | R162: 45107 | S162: 0.6664 | U162: =EOMONTH(V162,0) -> 45107 | V162: 45107 | W162: 4450.38 | Y162: =EOMONTH(Z162,0) -> 45961 | Z162: 45961 | AA162: 72 | AG162: =EOMONTH(AH162,0) -> 45473 | AH162: 45473 | AI162: 48.3
A163: =EOMONTH(B163,0) -> 45138 | B163: 45138 | C163: 146.3143 | E163: =EOMONTH(F163,0) -> 45777 | F163: 45777 | G163: 93.82 | I163: =EOMONTH(J163,0) -> 45138 | J163: 45138 | K163: 400.8 | M163: =EOMONTH(N163,0) -> 45138 | N163: 45138 | O163: 2282.5 | Q163: =EOMONTH(R163,0) -> 45138 | R163: 45138 | S163: 0.6717 | U163: =EOMONTH(V163,0) -> 45138 | V163: 45138 | W163: 4588.96 | Y163: =EOMONTH(Z163,0) -> 45991 | Z163: 45991 | AA163: 69.87 | AG163: =EOMONTH(AH163,0) -> 45504 | AH163: 45504 | AI163: 47.4
A164: =EOMONTH(B164,0) -> 45169 | B164: 45169 | C164: 141.3745 | E164: =EOMONTH(F164,0) -> 45808 | F164: 45808 | G164: 91.91 | I164: =EOMONTH(J164,0) -> 45169 | J164: 45169 | K164: 377.25 | M164: =EOMONTH(N164,0) -> 45169 | N164: 45169 | O164: 2208 | Q164: =EOMONTH(R164,0) -> 45169 | R164: 45169 | S164: 0.6484 | U164: =EOMONTH(V164,0) -> 45169 | V164: 45169 | W164: 4507.66 | Y164: =EOMONTH(Z164,0) -> 46022 | Z164: 46022 | AA164: 68.18 | AG164: =EOMONTH(AH164,0) -> 45535 | AH164: 45535 | AI164: 47.7
A165: =EOMONTH(B165,0) -> 45199 | B165: 45198 | C165: 143.9532 | E165: =EOMONTH(F165,0) -> 45838 | F165: 45838 | G165: 88.61 | I165: =EOMONTH(J165,0) -> 45199 | J165: 45198 | K165: 373.75 | M165: =EOMONTH(N165,0) -> 45199 | N165: 45198 | O165: 2347 | Q165: =EOMONTH(R165,0) -> 45199 | R165: 45198 | S165: 0.6435 | U165: =EOMONTH(V165,0) -> 45199 | V165: 45198 | W165: 4288.05 | AG165: =EOMONTH(AH165,0) -> 45565 | AH165: 45565 | AI165: 47.3
A166: =EOMONTH(B166,0) -> 45230 | B166: 45230 | C166: 145.5365 | E166: =EOMONTH(F166,0) -> 45869 | F166: 45869 | G166: 95.73 | I166: =EOMONTH(J166,0) -> 45230 | J166: 45230 | K166: 364.9 | M166: =EOMONTH(N166,0) -> 45230 | N166: 45230 | O166: 2251.5 | Q166: =EOMONTH(R166,0) -> 45230 | R166: 45230 | S166: 0.6337 | U166: =EOMONTH(V166,0) -> 45230 | V166: 45230 | W166: 4193.8 | AG166: =EOMONTH(AH166,0) -> 45596 | AH166: 45596 | AI166: 47
A167: =EOMONTH(B167,0) -> 45260 | B167: 45260 | C167: 156.281 | E167: =EOMONTH(F167,0) -> 45900 | F167: 45900 | G167: 98.14 | I167: =EOMONTH(J167,0) -> 45260 | J167: 45260 | K167: 382.9 | M167: =EOMONTH(N167,0) -> 45260 | N167: 45260 | O167: 2193 | Q167: =EOMONTH(R167,0) -> 45260 | R167: 45260 | S167: 0.6605 | U167: =EOMONTH(V167,0) -> 45260 | V167: 45260 | W167: 4567.8 | AG167: =EOMONTH(AH167,0) -> 45626 | AH167: 45626 | AI167: 48.4
A168: =EOMONTH(B168,0) -> 45291 | B168: 45289 | C168: 168.4279 | E168: =EOMONTH(F168,0) -> 45930 | F168: 45930 | G168: 98.16 | I168: =EOMONTH(J168,0) -> 45291 | J168: 45289 | K168: 389.05 | M168: =EOMONTH(N168,0) -> 45291 | N168: 45289 | O168: 2384 | Q168: =EOMONTH(R168,0) -> 45291 | R168: 45289 | S168: 0.6812 | U168: =EOMONTH(V168,0) -> 45291 | V168: 45289 | W168: 4769.83 | AG168: =EOMONTH(AH168,0) -> 45657 | AH168: 45657 | AI168: 49.2
A169: =EOMONTH(B169,0) -> 45322 | B169: 45322 | C169: 156.6882 | E169: =EOMONTH(F169,0) -> 45961 | F169: 45961 | G169: 101.46 | I169: =EOMONTH(J169,0) -> 45322 | J169: 45322 | K169: 390.6 | M169: =EOMONTH(N169,0) -> 45322 | N169: 45322 | O169: 2280 | Q169: =EOMONTH(R169,0) -> 45322 | R169: 45322 | S169: 0.6568 | U169: =EOMONTH(V169,0) -> 45322 | V169: 45322 | W169: 4845.65 | AG169: =EOMONTH(AH169,0) -> 45688 | AH169: 45688 | AI169: 50.5
A170: =EOMONTH(B170,0) -> 45351 | B170: 45351 | C170: 145.9663 | E170: =EOMONTH(F170,0) -> 45991 | F170: 45991 | G170: 101.01 | I170: =EOMONTH(J170,0) -> 45351 | J170: 45351 | K170: 383.45 | M170: =EOMONTH(N170,0) -> 45351 | N170: 45351 | O170: 2228 | Q170: =EOMONTH(R170,0) -> 45351 | R170: 45351 | S170: 0.6497 | U170: =EOMONTH(V170,0) -> 45351 | V170: 45351 | W170: 5096.27 | AG170: =EOMONTH(AH170,0) -> 45716 | AH170: 45716 | AI170: 50
A171: =EOMONTH(B171,0) -> 45382 | B171: 45380 | C171: 150.0217 | E171: =EOMONTH(F171,0) -> 46022 | F171: 46022 | G171: 103.92 | I171: =EOMONTH(J171,0) -> 45382 | J171: 45380 | K171: 400.7 | M171: =EOMONTH(N171,0) -> 45382 | N171: 45380 | O171: 2337 | Q171: =EOMONTH(R171,0) -> 45382 | R171: 45380 | S171: 0.6521 | U171: =EOMONTH(V171,0) -> 45382 | V171: 45380 | W171: 5254.35 | AG171: =EOMONTH(AH171,0) -> 45747 | AH171: 45747 | AI171: 48.9
A172: =EOMONTH(B172,0) -> 45412 | B172: 45412 | C172: 159.6481 | E172: =EOMONTH(F172,0) -> 46053 | F172: 46053 | G172: 103.61 | I172: =EOMONTH(J172,0) -> 45412 | J172: 45412 | K172: 456.45 | M172: =EOMONTH(N172,0) -> 45412 | N172: 45412 | O172: 2591.5 | Q172: =EOMONTH(R172,0) -> 45412 | R172: 45412 | S172: 0.6473 | U172: =EOMONTH(V172,0) -> 45412 | V172: 45412 | W172: 5035.69 | AG172: =EOMONTH(AH172,0) -> 45777 | AH172: 45777 | AI172: 48.8
A173: =EOMONTH(B173,0) -> 45443 | B173: 45443 | C173: 164.9909 | E173: =EOMONTH(F173,0) -> 46081 | F173: 46081 | G173: 99.47 | I173: =EOMONTH(J173,0) -> 45443 | J173: 45443 | K173: 460.2 | M173: =EOMONTH(N173,0) -> 45443 | N173: 45443 | O173: 2652.5 | Q173: =EOMONTH(R173,0) -> 45443 | R173: 45443 | S173: 0.6653 | U173: =EOMONTH(V173,0) -> 45443 | V173: 45443 | W173: 5277.51 | AG173: =EOMONTH(AH173,0) -> 45808 | AH173: 45808 | AI173: 48.6
A174: =EOMONTH(B174,0) -> 45473 | B174: 45471 | C174: 155.1762 | I174: =EOMONTH(J174,0) -> 45473 | J174: 45471 | K174: 439.05 | M174: =EOMONTH(N174,0) -> 45473 | N174: 45471 | O174: 2524.5 | Q174: =EOMONTH(R174,0) -> 45473 | R174: 45471 | S174: 0.667 | U174: =EOMONTH(V174,0) -> 45473 | V174: 45471 | W174: 5460.48 | AG174: =EOMONTH(AH174,0) -> 45838 | AH174: 45838 | AI174: 49
A175: =EOMONTH(B175,0) -> 45504 | B175: 45504 | C175: 153.3639 | I175: =EOMONTH(J175,0) -> 45504 | J175: 45504 | K175: 417.65 | M175: =EOMONTH(N175,0) -> 45504 | N175: 45504 | O175: 2290.5 | Q175: =EOMONTH(R175,0) -> 45504 | R175: 45504 | S175: 0.6542 | U175: =EOMONTH(V175,0) -> 45504 | V175: 45504 | W175: 5522.3 | AG175: =EOMONTH(AH175,0) -> 45869 | AH175: 45869 | AI175: 48.4
A176: =EOMONTH(B176,0) -> 45535 | B176: 45534 | C176: 153.2167 | I176: =EOMONTH(J176,0) -> 45535 | J176: 45534 | K176: 414.5 | M176: =EOMONTH(N176,0) -> 45535 | N176: 45534 | O176: 2447 | Q176: =EOMONTH(R176,0) -> 45535 | R176: 45534 | S176: 0.6765 | U176: =EOMONTH(V176,0) -> 45535 | V176: 45534 | W176: 5648.4 | AG176: =EOMONTH(AH176,0) -> 45900 | AH176: 45900 | AI176: 48.9
A177: =EOMONTH(B177,0) -> 45565 | B177: 45565 | C177: 172.3476 | I177: =EOMONTH(J177,0) -> 45565 | J177: 45565 | K177: 455.3 | M177: =EOMONTH(N177,0) -> 45565 | N177: 45565 | O177: 2611.5 | Q177: =EOMONTH(R177,0) -> 45565 | R177: 45565 | S177: 0.6913 | U177: =EOMONTH(V177,0) -> 45565 | V177: 45565 | W177: 5762.48 | AG177: =EOMONTH(AH177,0) -> 45930 | AH177: 45930 | AI177: 48.9
A178: =EOMONTH(B178,0) -> 45596 | B178: 45596 | C178: 157.1398 | I178: =EOMONTH(J178,0) -> 45596 | J178: 45596 | K178: 434 | M178: =EOMONTH(N178,0) -> 45596 | N178: 45596 | O178: 2617.5 | Q178: =EOMONTH(R178,0) -> 45596 | R178: 45596 | S178: 0.6582 | U178: =EOMONTH(V178,0) -> 45596 | V178: 45596 | W178: 5705.45 | AG178: =EOMONTH(AH178,0) -> 45961 | AH178: 45961 | AI178: 48.8
A179: =EOMONTH(B179,0) -> 45626 | B179: 45625 | C179: 152.1754 | I179: =EOMONTH(J179,0) -> 45626 | J179: 45625 | K179: 408.05 | M179: =EOMONTH(N179,0) -> 45626 | N179: 45625 | O179: 2594 | Q179: =EOMONTH(R179,0) -> 45626 | R179: 45625 | S179: 0.6512 | U179: =EOMONTH(V179,0) -> 45626 | V179: 45625 | W179: 6032.38 | AG179: =EOMONTH(AH179,0) -> 45991 | AH179: 45991 | AI179: 48
A180: =EOMONTH(B180,0) -> 45657 | B180: 45657 | C180: 142.4163 | I180: =EOMONTH(J180,0) -> 45657 | J180: 45657 | K180: 402.65 | M180: =EOMONTH(N180,0) -> 45657 | N180: 45657 | O180: 2551.5 | Q180: =EOMONTH(R180,0) -> 45657 | R180: 45657 | S180: 0.6188 | U180: =EOMONTH(V180,0) -> 45657 | V180: 45657 | W180: 5881.63 | AG180: =EOMONTH(AH180,0) -> 46022 | AH180: 46022 | AI180: 47.9
A181: =EOMONTH(B181,0) -> 45688 | B181: 45688 | C181: 146.2909 | I181: =EOMONTH(J181,0) -> 45688 | J181: 45688 | K181: 427.9 | M181: =EOMONTH(N181,0) -> 45688 | N181: 45688 | O181: 2594 | Q181: =EOMONTH(R181,0) -> 45688 | R181: 45688 | S181: 0.6218 | U181: =EOMONTH(V181,0) -> 45688 | V181: 45688 | W181: 6040.53 | AG181: =EOMONTH(AH181,0) -> 46053 | AH181: 46053 | AI181: 52.6
...

Sheet Monthly_Prices_RAW
B2: Month_end | C2: RIO | D2: IronOre | E2: Copper | F2: Aluminum | G2: AUDUSD | H2: SPX | I2: PMI
B3: 40268 | C3: =_xlfn.XLOOKUP($B3,'Raw Data'!$A3:$A194,'Raw Data'!$C3:$C194,0) -> 59.1825 | E3: =_xlfn.XLOOKUP($B3,'Raw Data'!$I3:$I194,'Raw Data'!$K3:$K194,"") -> 355.35 | F3: =_xlfn.XLOOKUP($B3,'Raw Data'!$M3:$M194,'Raw Data'!$O3:$O194,"") -> 2323 | G3: =_xlfn.XLOOKUP($B3,'Raw Data'!$Q3:$Q194,'Raw Data'!$S3:$S194,"") -> 0.9172 | H3: =_xlfn.XLOOKUP($B3,'Raw Data'!$U3:$U194,'Raw Data'!$W3:$W194,"") -> 1169.43
B4: 40298 | C4: =_xlfn.XLOOKUP($B4,'Raw Data'!$A4:$A195,'Raw Data'!$C4:$C195,0) -> 50.86 | E4: =_xlfn.XLOOKUP($B4,'Raw Data'!$I4:$I195,'Raw Data'!$K4:$K195,"") -> 333.75 | F4: =_xlfn.XLOOKUP($B4,'Raw Data'!$M4:$M195,'Raw Data'!$O4:$O195,"") -> 2255 | G4: =_xlfn.XLOOKUP($B4,'Raw Data'!$Q4:$Q195,'Raw Data'!$S4:$S195,"") -> 0.9243 | H4: =_xlfn.XLOOKUP($B4,'Raw Data'!$U4:$U195,'Raw Data'!$W4:$W195,"") -> 1186.69
B5: 40329 | C5: =_xlfn.XLOOKUP($B5,'Raw Data'!$A5:$A196,'Raw Data'!$C5:$C196,0) -> 46.1 | E5: =_xlfn.XLOOKUP($B5,'Raw Data'!$I5:$I196,'Raw Data'!$K5:$K196,"") -> 310.45 | F5: =_xlfn.XLOOKUP($B5,'Raw Data'!$M5:$M196,'Raw Data'!$O5:$O196,"") -> 2043 | G5: =_xlfn.XLOOKUP($B5,'Raw Data'!$Q5:$Q196,'Raw Data'!$S5:$S196,"") -> 0.8459 | H5: =_xlfn.XLOOKUP($B5,'Raw Data'!$U5:$U196,'Raw Data'!$W5:$W196,"") -> 1089.41
B6: 40359 | C6: =_xlfn.XLOOKUP($B6,'Raw Data'!$A6:$A197,'Raw Data'!$C6:$C197,0) -> 43.6 | E6: =_xlfn.XLOOKUP($B6,'Raw Data'!$I6:$I197,'Raw Data'!$K6:$K197,"") -> 293.6 | F6: =_xlfn.XLOOKUP($B6,'Raw Data'!$M6:$M197,'Raw Data'!$O6:$O197,"") -> 1977.5 | G6: =_xlfn.XLOOKUP($B6,'Raw Data'!$Q6:$Q197,'Raw Data'!$S6:$S197,"") -> 0.8408 | H6: =_xlfn.XLOOKUP($B6,'Raw Data'!$U6:$U197,'Raw Data'!$W6:$W197,"") -> 1030.71
B7: 40390 | C7: =_xlfn.XLOOKUP($B7,'Raw Data'!$A7:$A198,'Raw Data'!$C7:$C198,0) -> 51.92 | E7: =_xlfn.XLOOKUP($B7,'Raw Data'!$I7:$I198,'Raw Data'!$K7:$K198,"") -> 331.15 | F7: =_xlfn.XLOOKUP($B7,'Raw Data'!$M7:$M198,'Raw Data'!$O7:$O198,"") -> 2175 | G7: =_xlfn.XLOOKUP($B7,'Raw Data'!$Q7:$Q198,'Raw Data'!$S7:$S198,"") -> 0.9042 | H7: =_xlfn.XLOOKUP($B7,'Raw Data'!$U7:$U198,'Raw Data'!$W7:$W198,"") -> 1101.6
B8: 40421 | C8: =_xlfn.XLOOKUP($B8,'Raw Data'!$A8:$A199,'Raw Data'!$C8:$C199,0) -> 50.8606 | E8: =_xlfn.XLOOKUP($B8,'Raw Data'!$I8:$I199,'Raw Data'!$K8:$K199,"") -> 336.1 | F8: =_xlfn.XLOOKUP($B8,'Raw Data'!$M8:$M199,'Raw Data'!$O8:$O199,"") -> 2058 | G8: =_xlfn.XLOOKUP($B8,'Raw Data'!$Q8:$Q199,'Raw Data'!$S8:$S199,"") -> 0.8906 | H8: =_xlfn.XLOOKUP($B8,'Raw Data'!$U8:$U199,'Raw Data'!$W8:$W199,"") -> 1049.33
B9: 40451 | C9: =_xlfn.XLOOKUP($B9,'Raw Data'!$A9:$A200,'Raw Data'!$C9:$C200,0) -> 59.2314 | E9: =_xlfn.XLOOKUP($B9,'Raw Data'!$I9:$I200,'Raw Data'!$K9:$K200,"") -> 365.15 | F9: =_xlfn.XLOOKUP($B9,'Raw Data'!$M9:$M200,'Raw Data'!$O9:$O200,"") -> 2351 | G9: =_xlfn.XLOOKUP($B9,'Raw Data'!$Q9:$Q200,'Raw Data'!$S9:$S200,"") -> 0.9671 | H9: =_xlfn.XLOOKUP($B9,'Raw Data'!$U9:$U200,'Raw Data'!$W9:$W200,"") -> 1141.2
B10: 40482 | C10: =_xlfn.XLOOKUP($B10,'Raw Data'!$A10:$A201,'Raw Data'!$C10:$C201,0) -> 65.676 | E10: =_xlfn.XLOOKUP($B10,'Raw Data'!$I10:$I201,'Raw Data'!$K10:$K201,"") -> 373.35 | F10: =_xlfn.XLOOKUP($B10,'Raw Data'!$M10:$M201,'Raw Data'!$O10:$O201,"") -> 2344 | G10: =_xlfn.XLOOKUP($B10,'Raw Data'!$Q10:$Q201,'Raw Data'!$S10:$S201,"") -> 0.9835 | H10: =_xlfn.XLOOKUP($B10,'Raw Data'!$U10:$U201,'Raw Data'!$W10:$W201,"") -> 1183.26
B11: 40512 | C11: =_xlfn.XLOOKUP($B11,'Raw Data'!$A11:$A202,'Raw Data'!$C11:$C202,0) -> 64.6775 | E11: =_xlfn.XLOOKUP($B11,'Raw Data'!$I11:$I202,'Raw Data'!$K11:$K202,"") -> 382.3 | F11: =_xlfn.XLOOKUP($B11,'Raw Data'!$M11:$M202,'Raw Data'!$O11:$O202,"") -> 2275 | G11: =_xlfn.XLOOKUP($B11,'Raw Data'!$Q11:$Q202,'Raw Data'!$S11:$S202,"") -> 0.9588 | H11: =_xlfn.XLOOKUP($B11,'Raw Data'!$U11:$U202,'Raw Data'!$W11:$W202,"") -> 1180.55
B12: 40543 | C12: =_xlfn.XLOOKUP($B12,'Raw Data'!$A12:$A203,'Raw Data'!$C12:$C203,0) -> 72.2718 | E12: =_xlfn.XLOOKUP($B12,'Raw Data'!$I12:$I203,'Raw Data'!$K12:$K203,"") -> 444.7 | F12: =_xlfn.XLOOKUP($B12,'Raw Data'!$M12:$M203,'Raw Data'!$O12:$O203,"") -> 2470 | G12: =_xlfn.XLOOKUP($B12,'Raw Data'!$Q12:$Q203,'Raw Data'!$S12:$S203,"") -> 1.0233 | H12: =_xlfn.XLOOKUP($B12,'Raw Data'!$U12:$U203,'Raw Data'!$W12:$W203,"") -> 1257.64
B13: 40574 | C13: =_xlfn.XLOOKUP($B13,'Raw Data'!$A13:$A204,'Raw Data'!$C13:$C204,0) -> 70.0732 | E13: =_xlfn.XLOOKUP($B13,'Raw Data'!$I13:$I204,'Raw Data'!$K13:$K204,"") -> 445.85 | F13: =_xlfn.XLOOKUP($B13,'Raw Data'!$M13:$M204,'Raw Data'!$O13:$O204,"") -> 2520 | G13: =_xlfn.XLOOKUP($B13,'Raw Data'!$Q13:$Q204,'Raw Data'!$S13:$S204,"") -> 0.9974 | H13: =_xlfn.XLOOKUP($B13,'Raw Data'!$U13:$U204,'Raw Data'!$W13:$W204,"") -> 1286.12
B14: 40602 | C14: =_xlfn.XLOOKUP($B14,'Raw Data'!$A14:$A205,'Raw Data'!$C14:$C205,0) -> 71.6869 | E14: =_xlfn.XLOOKUP($B14,'Raw Data'!$I14:$I205,'Raw Data'!$K14:$K205,"") -> 447.8 | F14: =_xlfn.XLOOKUP($B14,'Raw Data'!$M14:$M205,'Raw Data'!$O14:$O205,"") -> 2600 | G14: =_xlfn.XLOOKUP($B14,'Raw Data'!$Q14:$Q205,'Raw Data'!$S14:$S205,"") -> 1.0186 | H14: =_xlfn.XLOOKUP($B14,'Raw Data'!$U14:$U205,'Raw Data'!$W14:$W205,"") -> 1327.22
B15: 40633 | C15: =_xlfn.XLOOKUP($B15,'Raw Data'!$A15:$A206,'Raw Data'!$C15:$C206,0) -> 72.3756 | E15: =_xlfn.XLOOKUP($B15,'Raw Data'!$I15:$I206,'Raw Data'!$K15:$K206,"") -> 430.75 | F15: =_xlfn.XLOOKUP($B15,'Raw Data'!$M15:$M206,'Raw Data'!$O15:$O206,"") -> 2648 | G15: =_xlfn.XLOOKUP($B15,'Raw Data'!$Q15:$Q206,'Raw Data'!$S15:$S206,"") -> 1.0329 | H15: =_xlfn.XLOOKUP($B15,'Raw Data'!$U15:$U206,'Raw Data'!$W15:$W206,"") -> 1325.83 | I15: =_xlfn.XLOOKUP($B15,'Raw Data'!$AG3:$AG182,'Raw Data'!$AI3:$AI182,"") -> 58.4
B16: 40663 | C16: =_xlfn.XLOOKUP($B16,'Raw Data'!$A16:$A207,'Raw Data'!$C16:$C207,0) -> 74.5025 | E16: =_xlfn.XLOOKUP($B16,'Raw Data'!$I16:$I207,'Raw Data'!$K16:$K207,"") -> 416.55 | F16: =_xlfn.XLOOKUP($B16,'Raw Data'!$M16:$M207,'Raw Data'!$O16:$O207,"") -> 2767.5 | G16: =_xlfn.XLOOKUP($B16,'Raw Data'!$Q16:$Q207,'Raw Data'!$S16:$S207,"") -> 1.0971 | H16: =_xlfn.XLOOKUP($B16,'Raw Data'!$U16:$U207,'Raw Data'!$W16:$W207,"") -> 1363.61 | I16: =_xlfn.XLOOKUP($B16,'Raw Data'!$AG4:$AG183,'Raw Data'!$AI4:$AI183,"") -> 57.9
B17: 40694 | C17: =_xlfn.XLOOKUP($B17,'Raw Data'!$A17:$A208,'Raw Data'!$C17:$C208,0) -> 71.358 | E17: =_xlfn.XLOOKUP($B17,'Raw Data'!$I17:$I208,'Raw Data'!$K17:$K208,"") -> 417.75 | F17: =_xlfn.XLOOKUP($B17,'Raw Data'!$M17:$M208,'Raw Data'!$O17:$O208,"") -> 2675 | G17: =_xlfn.XLOOKUP($B17,'Raw Data'!$Q17:$Q208,'Raw Data'!$S17:$S208,"") -> 1.0672 | H17: =_xlfn.XLOOKUP($B17,'Raw Data'!$U17:$U208,'Raw Data'!$W17:$W208,"") -> 1345.2 | I17: =_xlfn.XLOOKUP($B17,'Raw Data'!$AG5:$AG184,'Raw Data'!$AI5:$AI184,"") -> 54.8
B18: 40724 | C18: =_xlfn.XLOOKUP($B18,'Raw Data'!$A18:$A209,'Raw Data'!$C18:$C209,0) -> 73.5968 | E18: =_xlfn.XLOOKUP($B18,'Raw Data'!$I18:$I209,'Raw Data'!$K18:$K209,"") -> 427.2 | F18: =_xlfn.XLOOKUP($B18,'Raw Data'!$M18:$M209,'Raw Data'!$O18:$O209,"") -> 2532 | G18: =_xlfn.XLOOKUP($B18,'Raw Data'!$Q18:$Q209,'Raw Data'!$S18:$S209,"") -> 1.0722 | H18: =_xlfn.XLOOKUP($B18,'Raw Data'!$U18:$U209,'Raw Data'!$W18:$W209,"") -> 1320.64 | I18: =_xlfn.XLOOKUP($B18,'Raw Data'!$AG6:$AG185,'Raw Data'!$AI6:$AI185,"") -> 55.8
B19: 40755 | C19: =_xlfn.XLOOKUP($B19,'Raw Data'!$A19:$A210,'Raw Data'!$C19:$C210,0) -> 72.2332 | E19: =_xlfn.XLOOKUP($B19,'Raw Data'!$I19:$I210,'Raw Data'!$K19:$K210,"") -> 447.95 | F19: =_xlfn.XLOOKUP($B19,'Raw Data'!$M19:$M210,'Raw Data'!$O19:$O210,"") -> 2624 | G19: =_xlfn.XLOOKUP($B19,'Raw Data'!$Q19:$Q210,'Raw Data'!$S19:$S210,"") -> 1.0993 | H19: =_xlfn.XLOOKUP($B19,'Raw Data'!$U19:$U210,'Raw Data'!$W19:$W210,"") -> 1292.28 | I19: =_xlfn.XLOOKUP($B19,'Raw Data'!$AG7:$AG186,'Raw Data'!$AI7:$AI186,"") -> 52.9
B20: 40786 | C20: =_xlfn.XLOOKUP($B20,'Raw Data'!$A20:$A211,'Raw Data'!$C20:$C211,0) -> 62.8435 | E20: =_xlfn.XLOOKUP($B20,'Raw Data'!$I20:$I211,'Raw Data'!$K20:$K211,"") -> 418.7 | F20: =_xlfn.XLOOKUP($B20,'Raw Data'!$M20:$M211,'Raw Data'!$O20:$O211,"") -> 2469 | G20: =_xlfn.XLOOKUP($B20,'Raw Data'!$Q20:$Q211,'Raw Data'!$S20:$S211,"") -> 1.0707 | H20: =_xlfn.XLOOKUP($B20,'Raw Data'!$U20:$U211,'Raw Data'!$W20:$W211,"") -> 1218.89 | I20: =_xlfn.XLOOKUP($B20,'Raw Data'!$AG8:$AG187,'Raw Data'!$AI8:$AI187,"") -> 52.6
B21: 40816 | C21: =_xlfn.XLOOKUP($B21,'Raw Data'!$A21:$A212,'Raw Data'!$C21:$C212,0) -> 45.2934 | E21: =_xlfn.XLOOKUP($B21,'Raw Data'!$I21:$I212,'Raw Data'!$K21:$K212,"") -> 315.2 | F21: =_xlfn.XLOOKUP($B21,'Raw Data'!$M21:$M212,'Raw Data'!$O21:$O212,"") -> 2157 | G21: =_xlfn.XLOOKUP($B21,'Raw Data'!$Q21:$Q212,'Raw Data'!$S21:$S212,"") -> 0.9662 | H21: =_xlfn.XLOOKUP($B21,'Raw Data'!$U21:$U212,'Raw Data'!$W21:$W212,"") -> 1131.42 | I21: =_xlfn.XLOOKUP($B21,'Raw Data'!$AG9:$AG188,'Raw Data'!$AI9:$AI188,"") -> 53.7
B22: 40847 | C22: =_xlfn.XLOOKUP($B22,'Raw Data'!$A22:$A213,'Raw Data'!$C22:$C213,0) -> 55.5481 | E22: =_xlfn.XLOOKUP($B22,'Raw Data'!$I22:$I213,'Raw Data'!$K22:$K213,"") -> 363.2 | F22: =_xlfn.XLOOKUP($B22,'Raw Data'!$M22:$M213,'Raw Data'!$O22:$O213,"") -> 2218 | G22: =_xlfn.XLOOKUP($B22,'Raw Data'!$Q22:$Q213,'Raw Data'!$S22:$S213,"") -> 1.053 | H22: =_xlfn.XLOOKUP($B22,'Raw Data'!$U22:$U213,'Raw Data'!$W22:$W213,"") -> 1253.3 | I22: =_xlfn.XLOOKUP($B22,'Raw Data'!$AG10:$AG189,'Raw Data'!$AI10:$AI189,"") -> 51.4
B23: 40877 | C23: =_xlfn.XLOOKUP($B23,'Raw Data'!$A23:$A214,'Raw Data'!$C23:$C214,0) -> 54.5308 | E23: =_xlfn.XLOOKUP($B23,'Raw Data'!$I23:$I214,'Raw Data'!$K23:$K214,"") -> 356.3 | F23: =_xlfn.XLOOKUP($B23,'Raw Data'!$M23:$M214,'Raw Data'!$O23:$O214,"") -> 2110 | G23: =_xlfn.XLOOKUP($B23,'Raw Data'!$Q23:$Q214,'Raw Data'!$S23:$S214,"") -> 1.0283 | H23: =_xlfn.XLOOKUP($B23,'Raw Data'!$U23:$U214,'Raw Data'!$W23:$W214,"") -> 1246.96 | I23: =_xlfn.XLOOKUP($B23,'Raw Data'!$AG11:$AG190,'Raw Data'!$AI11:$AI190,"") -> 51.8
B24: 40908 | C24: =_xlfn.XLOOKUP($B24,'Raw Data'!$A24:$A215,'Raw Data'!$C24:$C215,0) -> 50.2666 | D24: =_xlfn.XLOOKUP($B24,'Raw Data'!$E3:$E173,'Raw Data'!$G3:$G173,"") -> 138.2 | E24: =_xlfn.XLOOKUP($B24,'Raw Data'!$I24:$I215,'Raw Data'!$K24:$K215,"") -> 343.6 | F24: =_xlfn.XLOOKUP($B24,'Raw Data'!$M24:$M215,'Raw Data'!$O24:$O215,"") -> 2020 | G24: =_xlfn.XLOOKUP($B24,'Raw Data'!$Q24:$Q215,'Raw Data'!$S24:$S215,"") -> 1.0209 | H24: =_xlfn.XLOOKUP($B24,'Raw Data'!$U24:$U215,'Raw Data'!$W24:$W215,"") -> 1257.61 | I24: =_xlfn.XLOOKUP($B24,'Raw Data'!$AG12:$AG191,'Raw Data'!$AI12:$AI191,"") -> 53
B25: 40939 | C25: =_xlfn.XLOOKUP($B25,'Raw Data'!$A25:$A216,'Raw Data'!$C25:$C216,0) -> 62.1242 | D25: =_xlfn.XLOOKUP($B25,'Raw Data'!$E4:$E174,'Raw Data'!$G4:$G174,"") -> 141.8 | E25: =_xlfn.XLOOKUP($B25,'Raw Data'!$I25:$I216,'Raw Data'!$K25:$K216,"") -> 379 | F25: =_xlfn.XLOOKUP($B25,'Raw Data'!$M25:$M216,'Raw Data'!$O25:$O216,"") -> 2238 | G25: =_xlfn.XLOOKUP($B25,'Raw Data'!$Q25:$Q216,'Raw Data'!$S25:$S216,"") -> 1.0621 | H25: =_xlfn.XLOOKUP($B25,'Raw Data'!$U25:$U216,'Raw Data'!$W25:$W216,"") -> 1312.41 | I25: =_xlfn.XLOOKUP($B25,'Raw Data'!$AG13:$AG192,'Raw Data'!$AI13:$AI192,"") -> 54.2
B26: 40968 | C26: =_xlfn.XLOOKUP($B26,'Raw Data'!$A26:$A217,'Raw Data'!$C26:$C217,0) -> 59.4379 | D26: =_xlfn.XLOOKUP($B26,'Raw Data'!$E5:$E175,'Raw Data'!$G5:$G175,"") -> 141.4 | E26: =_xlfn.XLOOKUP($B26,'Raw Data'!$I26:$I217,'Raw Data'!$K26:$K217,"") -> 387.05 | F26: =_xlfn.XLOOKUP($B26,'Raw Data'!$M26:$M217,'Raw Data'!$O26:$O217,"") -> 2328 | G26: =_xlfn.XLOOKUP($B26,'Raw Data'!$Q26:$Q217,'Raw Data'!$S26:$S217,"") -> 1.0732 | H26: =_xlfn.XLOOKUP($B26,'Raw Data'!$U26:$U217,'Raw Data'!$W26:$W217,"") -> 1365.68 | I26: =_xlfn.XLOOKUP($B26,'Raw Data'!$AG14:$AG193,'Raw Data'!$AI14:$AI193,"") -> 53.3
B27: 40999 | C27: =_xlfn.XLOOKUP($B27,'Raw Data'!$A27:$A218,'Raw Data'!$C27:$C218,0) -> 58.0388 | D27: =_xlfn.XLOOKUP($B27,'Raw Data'!$E6:$E176,'Raw Data'!$G6:$G176,"") -> 145.1 | E27: =_xlfn.XLOOKUP($B27,'Raw Data'!$I27:$I218,'Raw Data'!$K27:$K218,"") -> 382.5 | F27: =_xlfn.XLOOKUP($B27,'Raw Data'!$M27:$M218,'Raw Data'!$O27:$O218,"") -> 2126 | G27: =_xlfn.XLOOKUP($B27,'Raw Data'!$Q27:$Q218,'Raw Data'!$S27:$S218,"") -> 1.0346 | H27: =_xlfn.XLOOKUP($B27,'Raw Data'!$U27:$U218,'Raw Data'!$W27:$W218,"") -> 1408.47 | I27: =_xlfn.XLOOKUP($B27,'Raw Data'!$AG15:$AG194,'Raw Data'!$AI15:$AI194,"") -> 53.5
B28: 41029 | C28: =_xlfn.XLOOKUP($B28,'Raw Data'!$A28:$A219,'Raw Data'!$C28:$C219,0) -> 58.54 | D28: =_xlfn.XLOOKUP($B28,'Raw Data'!$E7:$E177,'Raw Data'!$G7:$G177,"") -> 145.1 | E28: =_xlfn.XLOOKUP($B28,'Raw Data'!$I28:$I219,'Raw Data'!$K28:$K219,"") -> 383.35 | F28: =_xlfn.XLOOKUP($B28,'Raw Data'!$M28:$M219,'Raw Data'!$O28:$O219,"") -> 2119 | G28: =_xlfn.XLOOKUP($B28,'Raw Data'!$Q28:$Q219,'Raw Data'!$S28:$S219,"") -> 1.0429 | H28: =_xlfn.XLOOKUP($B28,'Raw Data'!$U28:$U219,'Raw Data'!$W28:$W219,"") -> 1397.91 | I28: =_xlfn.XLOOKUP($B28,'Raw Data'!$AG16:$AG195,'Raw Data'!$AI16:$AI195,"") -> 55.2
B29: 41060 | C29: =_xlfn.XLOOKUP($B29,'Raw Data'!$A29:$A220,'Raw Data'!$C29:$C220,0) -> 45.1239 | D29: =_xlfn.XLOOKUP($B29,'Raw Data'!$E8:$E178,'Raw Data'!$G8:$G178,"") -> 131.8 | E29: =_xlfn.XLOOKUP($B29,'Raw Data'!$I29:$I220,'Raw Data'!$K29:$K220,"") -> 336.55 | F29: =_xlfn.XLOOKUP($B29,'Raw Data'!$M29:$M220,'Raw Data'!$O29:$O220,"") -> 1994 | G29: =_xlfn.XLOOKUP($B29,'Raw Data'!$Q29:$Q220,'Raw Data'!$S29:$S220,"") -> 0.9734 | H29: =_xlfn.XLOOKUP($B29,'Raw Data'!$U29:$U220,'Raw Data'!$W29:$W220,"") -> 1310.33 | I29: =_xlfn.XLOOKUP($B29,'Raw Data'!$AG17:$AG196,'Raw Data'!$AI17:$AI196,"") -> 53.2
B30: 41090 | C30: =_xlfn.XLOOKUP($B30,'Raw Data'!$A30:$A221,'Raw Data'!$C30:$C221,0) -> 49.9161 | D30: =_xlfn.XLOOKUP($B30,'Raw Data'!$E9:$E179,'Raw Data'!$G9:$G179,"") -> 135.1 | E30: =_xlfn.XLOOKUP($B30,'Raw Data'!$I30:$I221,'Raw Data'!$K30:$K221,"") -> 349 | F30: =_xlfn.XLOOKUP($B30,'Raw Data'!$M30:$M221,'Raw Data'!$O30:$O221,"") -> 1911 | G30: =_xlfn.XLOOKUP($B30,'Raw Data'!$Q30:$Q221,'Raw Data'!$S30:$S221,"") -> 1.0238 | H30: =_xlfn.XLOOKUP($B30,'Raw Data'!$U30:$U221,'Raw Data'!$W30:$W221,"") -> 1362.16 | I30: =_xlfn.XLOOKUP($B30,'Raw Data'!$AG18:$AG197,'Raw Data'!$AI18:$AI197,"") -> 49.5
B31: 41121 | C31: =_xlfn.XLOOKUP($B31,'Raw Data'!$A31:$A222,'Raw Data'!$C31:$C222,0) -> 48.2456 | D31: =_xlfn.XLOOKUP($B31,'Raw Data'!$E10:$E180,'Raw Data'!$G10:$G180,"") -> 119.2 | E31: =_xlfn.XLOOKUP($B31,'Raw Data'!$I31:$I222,'Raw Data'!$K31:$K222,"") -> 341.75 | F31: =_xlfn.XLOOKUP($B31,'Raw Data'!$M31:$M222,'Raw Data'!$O31:$O222,"") -> 1889 | G31: =_xlfn.XLOOKUP($B31,'Raw Data'!$Q31:$Q222,'Raw Data'!$S31:$S222,"") -> 1.0503 | H31: =_xlfn.XLOOKUP($B31,'Raw Data'!$U31:$U222,'Raw Data'!$W31:$W222,"") -> 1379.32 | I31: =_xlfn.XLOOKUP($B31,'Raw Data'!$AG19:$AG198,'Raw Data'!$AI19:$AI198,"") -> 49.6
B32: 41152 | C32: =_xlfn.XLOOKUP($B32,'Raw Data'!$A32:$A223,'Raw Data'!$C32:$C223,0) -> 46.4704 | D32: =_xlfn.XLOOKUP($B32,'Raw Data'!$E11:$E181,'Raw Data'!$G11:$G181,"") -> 89.8 | E32: =_xlfn.XLOOKUP($B32,'Raw Data'!$I32:$I223,'Raw Data'!$K32:$K223,"") -> 345.4 | F32: =_xlfn.XLOOKUP($B32,'Raw Data'!$M32:$M223,'Raw Data'!$O32:$O223,"") -> 1902 | G32: =_xlfn.XLOOKUP($B32,'Raw Data'!$Q32:$Q223,'Raw Data'!$S32:$S223,"") -> 1.0322 | H32: =_xlfn.XLOOKUP($B32,'Raw Data'!$U32:$U223,'Raw Data'!$W32:$W223,"") -> 1406.58 | I32: =_xlfn.XLOOKUP($B32,'Raw Data'!$AG20:$AG199,'Raw Data'!$AI20:$AI199,"") -> 49
B33: 41182 | C33: =_xlfn.XLOOKUP($B33,'Raw Data'!$A33:$A224,'Raw Data'!$C33:$C224,0) -> 49.577 | D33: =_xlfn.XLOOKUP($B33,'Raw Data'!$E12:$E182,'Raw Data'!$G12:$G182,"") -> 106 | E33: =_xlfn.XLOOKUP($B33,'Raw Data'!$I33:$I224,'Raw Data'!$K33:$K224,"") -> 375.8 | F33: =_xlfn.XLOOKUP($B33,'Raw Data'!$M33:$M224,'Raw Data'!$O33:$O224,"") -> 2112 | G33: =_xlfn.XLOOKUP($B33,'Raw Data'!$Q33:$Q224,'Raw Data'!$S33:$S224,"") -> 1.0378 | H33: =_xlfn.XLOOKUP($B33,'Raw Data'!$U33:$U224,'Raw Data'!$W33:$W224,"") -> 1440.67 | I33: =_xlfn.XLOOKUP($B33,'Raw Data'!$AG21:$AG200,'Raw Data'!$AI21:$AI200,"") -> 50.8
B34: 41213 | C34: =_xlfn.XLOOKUP($B34,'Raw Data'!$A34:$A225,'Raw Data'!$C34:$C225,0) -> 52.9909 | D34: =_xlfn.XLOOKUP($B34,'Raw Data'!$E13:$E183,'Raw Data'!$G13:$G183,"") -> 119.3 | E34: =_xlfn.XLOOKUP($B34,'Raw Data'!$I34:$I225,'Raw Data'!$K34:$K225,"") -> 351.75 | F34: =_xlfn.XLOOKUP($B34,'Raw Data'!$M34:$M225,'Raw Data'!$O34:$O225,"") -> 1906 | G34: =_xlfn.XLOOKUP($B34,'Raw Data'!$Q34:$Q225,'Raw Data'!$S34:$S225,"") -> 1.0376 | H34: =_xlfn.XLOOKUP($B34,'Raw Data'!$U34:$U225,'Raw Data'!$W34:$W225,"") -> 1412.16 | I34: =_xlfn.XLOOKUP($B34,'Raw Data'!$AG22:$AG201,'Raw Data'!$AI22:$AI201,"") -> 50.5
B35: 41243 | C35: =_xlfn.XLOOKUP($B35,'Raw Data'!$A35:$A226,'Raw Data'!$C35:$C226,0) -> 52.8001 | D35: =_xlfn.XLOOKUP($B35,'Raw Data'!$E14:$E184,'Raw Data'!$G14:$G184,"") -> 116.7 | E35: =_xlfn.XLOOKUP($B35,'Raw Data'!$I35:$I226,'Raw Data'!$K35:$K226,"") -> 362.95 | F35: =_xlfn.XLOOKUP($B35,'Raw Data'!$M35:$M226,'Raw Data'!$O35:$O226,"") -> 2094 | G35: =_xlfn.XLOOKUP($B35,'Raw Data'!$Q35:$Q226,'Raw Data'!$S35:$S226,"") -> 1.0428 | H35: =_xlfn.XLOOKUP($B35,'Raw Data'!$U35:$U226,'Raw Data'!$W35:$W226,"") -> 1416.18 | I35: =_xlfn.XLOOKUP($B35,'Raw Data'!$AG23:$AG202,'Raw Data'!$AI23:$AI202,"") -> 48
... B194: 46081 | C194: =_xlfn.XLOOKUP($B194,'Raw Data'!$A194:$A385,'Raw Data'!$C194:$C385,0) -> 255.2755 | D194: =_xlfn.XLOOKUP($B194,'Raw Data'!$E173:$E343,'Raw Data'!$G173:$G343,"") -> 99.47 | E194: =_xlfn.XLOOKUP($B194,'Raw Data'!$I194:$I385,'Raw Data'!$K194:$K385,"") -> 600.45 | F194: =_xlfn.XLOOKUP($B194,'Raw Data'!$M194:$M385,'Raw Data'!$O194:$O385,"") -> 3140 | G194: =_xlfn.XLOOKUP($B194,'Raw Data'!$Q194:$Q385,'Raw Data'!$S194:$S385,"") -> 0.7118 | H194: =_xlfn.XLOOKUP($B194,'Raw Data'!$U194:$U385,'Raw Data'!$W194:$W385,"") -> 6878.88 | I194: =_xlfn.XLOOKUP($B194,'Raw Data'!$AG182:$AG361,'Raw Data'!$AI182:$AI361,"") -> 52.4

Sheet Monthly_Returns
A1: Month_end | B1: r_RIO | C1: r_IronOre | D1: r_Copper | E1: r_Aluminum | F1: r_AUDUSD | G1: r_SPX | H1: d_PMI
A2: =Monthly_Prices_RAW!B3 -> 40268 | B2: =IF(OR(Monthly_Prices_RAW!C4="",Monthly_Prices_RAW!C3=""),"",LN(Monthly_Prices_RAW!C4/Monthly_Prices_RAW!C3)) -> -0.15154913 | C2: =IF(OR(Monthly_Prices_RAW!D4="",Monthly_Prices_RAW!D3=""),"",LN(Monthly_Prices_RAW!D4/Monthly_Prices_RAW!D3)) | D2: =IF(OR(Monthly_Prices_RAW!E4="",Monthly_Prices_RAW!E3=""),"",LN(Monthly_Prices_RAW!E4/Monthly_Prices_RAW!E3)) -> -0.06271101 | E2: =IF(OR(Monthly_Prices_RAW!F4="",Monthly_Prices_RAW!F3=""),"",LN(Monthly_Prices_RAW!F4/Monthly_Prices_RAW!F3)) -> -0.029709481 | F2: =IF(OR(Monthly_Prices_RAW!G4="",Monthly_Prices_RAW!G3=""),"",LN(Monthly_Prices_RAW!G4/Monthly_Prices_RAW!G3)) -> 0.0077111433 | G2: =IF(OR(Monthly_Prices_RAW!H4="",Monthly_Prices_RAW!H3=""),"",LN(Monthly_Prices_RAW!H4/Monthly_Prices_RAW!H3)) -> 0.014651468 | H2: =IF(OR(Monthly_Prices_RAW!I4="",Monthly_Prices_RAW!I3=""),"",Monthly_Prices_RAW!I4-Monthly_Prices_RAW!I3)
A3: =Monthly_Prices_RAW!B4 -> 40298 | B3: =IF(OR(Monthly_Prices_RAW!C5="",Monthly_Prices_RAW!C4=""),"",LN(Monthly_Prices_RAW!C5/Monthly_Prices_RAW!C4)) -> -0.09826381 | C3: =IF(OR(Monthly_Prices_RAW!D5="",Monthly_Prices_RAW!D4=""),"",LN(Monthly_Prices_RAW!D5/Monthly_Prices_RAW!D4)) | D3: =IF(OR(Monthly_Prices_RAW!E5="",Monthly_Prices_RAW!E4=""),"",LN(Monthly_Prices_RAW!E5/Monthly_Prices_RAW!E4)) -> -0.072369352 | E3: =IF(OR(Monthly_Prices_RAW!F5="",Monthly_Prices_RAW!F4=""),"",LN(Monthly_Prices_RAW!F5/Monthly_Prices_RAW!F4)) -> -0.098730657 | F3: =IF(OR(Monthly_Prices_RAW!G5="",Monthly_Prices_RAW!G4=""),"",LN(Monthly_Prices_RAW!G5/Monthly_Prices_RAW!G4)) -> -0.088635545 | G3: =IF(OR(Monthly_Prices_RAW!H5="",Monthly_Prices_RAW!H4=""),"",LN(Monthly_Prices_RAW!H5/Monthly_Prices_RAW!H4)) -> -0.085531654 | H3: =IF(OR(Monthly_Prices_RAW!I5="",Monthly_Prices_RAW!I4=""),"",Monthly_Prices_RAW!I5-Monthly_Prices_RAW!I4)
A4: =Monthly_Prices_RAW!B5 -> 40329 | B4: =IF(OR(Monthly_Prices_RAW!C6="",Monthly_Prices_RAW!C5=""),"",LN(Monthly_Prices_RAW!C6/Monthly_Prices_RAW!C5)) -> -0.0557558 | C4: =IF(OR(Monthly_Prices_RAW!D6="",Monthly_Prices_RAW!D5=""),"",LN(Monthly_Prices_RAW!D6/Monthly_Prices_RAW!D5)) | D4: =IF(OR(Monthly_Prices_RAW!E6="",Monthly_Prices_RAW!E5=""),"",LN(Monthly_Prices_RAW!E6/Monthly_Prices_RAW!E5)) -> -0.055804561 | E4: =IF(OR(Monthly_Prices_RAW!F6="",Monthly_Prices_RAW!F5=""),"",LN(Monthly_Prices_RAW!F6/Monthly_Prices_RAW!F5)) -> -0.032585895 | F4: =IF(OR(Monthly_Prices_RAW!G6="",Monthly_Prices_RAW!G5=""),"",LN(Monthly_Prices_RAW!G6/Monthly_Prices_RAW!G5)) -> -0.0060473297 | G4: =IF(OR(Monthly_Prices_RAW!H6="",Monthly_Prices_RAW!H5=""),"",LN(Monthly_Prices_RAW!H6/Monthly_Prices_RAW!H5)) -> -0.05538838 | H4: =IF(OR(Monthly_Prices_RAW!I6="",Monthly_Prices_RAW!I5=""),"",Monthly_Prices_RAW!I6-Monthly_Prices_RAW!I5)
A5: =Monthly_Prices_RAW!B6 -> 40359 | B5: =IF(OR(Monthly_Prices_RAW!C7="",Monthly_Prices_RAW!C6=""),"",LN(Monthly_Prices_RAW!C7/Monthly_Prices_RAW!C6)) -> 0.17464692 | C5: =IF(OR(Monthly_Prices_RAW!D7="",Monthly_Prices_RAW!D6=""),"",LN(Monthly_Prices_RAW!D7/Monthly_Prices_RAW!D6)) | D5: =IF(OR(Monthly_Prices_RAW!E7="",Monthly_Prices_RAW!E6=""),"",LN(Monthly_Prices_RAW!E7/Monthly_Prices_RAW!E6)) -> 0.12035315 | E5: =IF(OR(Monthly_Prices_RAW!F7="",Monthly_Prices_RAW!F6=""),"",LN(Monthly_Prices_RAW!F7/Monthly_Prices_RAW!F6)) -> 0.095195244 | F5: =IF(OR(Monthly_Prices_RAW!G7="",Monthly_Prices_RAW!G6=""),"",LN(Monthly_Prices_RAW!G7/Monthly_Prices_RAW!G6)) -> 0.072696755 | G5: =IF(OR(Monthly_Prices_RAW!H7="",Monthly_Prices_RAW!H6=""),"",LN(Monthly_Prices_RAW!H7/Monthly_Prices_RAW!H6)) -> 0.066515783 | H5: =IF(OR(Monthly_Prices_RAW!I7="",Monthly_Prices_RAW!I6=""),"",Monthly_Prices_RAW!I7-Monthly_Prices_RAW!I6)
A6: =Monthly_Prices_RAW!B7 -> 40390 | B6: =IF(OR(Monthly_Prices_RAW!C8="",Monthly_Prices_RAW!C7=""),"",LN(Monthly_Prices_RAW!C8/Monthly_Prices_RAW!C7)) -> -0.020615515 | C6: =IF(OR(Monthly_Prices_RAW!D8="",Monthly_Prices_RAW!D7=""),"",LN(Monthly_Prices_RAW!D8/Monthly_Prices_RAW!D7)) | D6: =IF(OR(Monthly_Prices_RAW!E8="",Monthly_Prices_RAW!E7=""),"",LN(Monthly_Prices_RAW!E8/Monthly_Prices_RAW!E7)) -> 0.01483729 | E6: =IF(OR(Monthly_Prices_RAW!F8="",Monthly_Prices_RAW!F7=""),"",LN(Monthly_Prices_RAW!F8/Monthly_Prices_RAW!F7)) -> -0.055294027 | F6: =IF(OR(Monthly_Prices_RAW!G8="",Monthly_Prices_RAW!G7=""),"",LN(Monthly_Prices_RAW!G8/Monthly_Prices_RAW!G7)) -> -0.015155182 | G6: =IF(OR(Monthly_Prices_RAW!H8="",Monthly_Prices_RAW!H7=""),"",LN(Monthly_Prices_RAW!H8/Monthly_Prices_RAW!H7)) -> -0.048611803 | H6: =IF(OR(Monthly_Prices_RAW!I8="",Monthly_Prices_RAW!I7=""),"",Monthly_Prices_RAW!I8-Monthly_Prices_RAW!I7)
A7: =Monthly_Prices_RAW!B8 -> 40421 | B7: =IF(OR(Monthly_Prices_RAW!C9="",Monthly_Prices_RAW!C8=""),"",LN(Monthly_Prices_RAW!C9/Monthly_Prices_RAW!C8)) -> 0.15236325 | C7: =IF(OR(Monthly_Prices_RAW!D9="",Monthly_Prices_RAW!D8=""),"",LN(Monthly_Prices_RAW!D9/Monthly_Prices_RAW!D8)) | D7: =IF(OR(Monthly_Prices_RAW!E9="",Monthly_Prices_RAW!E8=""),"",LN(Monthly_Prices_RAW!E9/Monthly_Prices_RAW!E8)) -> 0.082899493 | E7: =IF(OR(Monthly_Prices_RAW!F9="",Monthly_Prices_RAW!F8=""),"",LN(Monthly_Prices_RAW!F9/Monthly_Prices_RAW!F8)) -> 0.13310613 | F7: =IF(OR(Monthly_Prices_RAW!G9="",Monthly_Prices_RAW!G8=""),"",LN(Monthly_Prices_RAW!G9/Monthly_Prices_RAW!G8)) -> 0.08240651 | G7: =IF(OR(Monthly_Prices_RAW!H9="",Monthly_Prices_RAW!H8=""),"",LN(Monthly_Prices_RAW!H9/Monthly_Prices_RAW!H8)) -> 0.083928475 | H7: =IF(OR(Monthly_Prices_RAW!I9="",Monthly_Prices_RAW!I8=""),"",Monthly_Prices_RAW!I9-Monthly_Prices_RAW!I8)
A8: =Monthly_Prices_RAW!B9 -> 40451 | B8: =IF(OR(Monthly_Prices_RAW!C10="",Monthly_Prices_RAW!C9=""),"",LN(Monthly_Prices_RAW!C10/Monthly_Prices_RAW!C9)) -> 0.10328176 | C8: =IF(OR(Monthly_Prices_RAW!D10="",Monthly_Prices_RAW!D9=""),"",LN(Monthly_Prices_RAW!D10/Monthly_Prices_RAW!D9)) | D8: =IF(OR(Monthly_Prices_RAW!E10="",Monthly_Prices_RAW!E9=""),"",LN(Monthly_Prices_RAW!E10/Monthly_Prices_RAW!E9)) -> 0.022208089 | E8: =IF(OR(Monthly_Prices_RAW!F10="",Monthly_Prices_RAW!F9=""),"",LN(Monthly_Prices_RAW!F10/Monthly_Prices_RAW!F9)) -> -0.0029818978 | F8: =IF(OR(Monthly_Prices_RAW!G10="",Monthly_Prices_RAW!G9=""),"",LN(Monthly_Prices_RAW!G10/Monthly_Prices_RAW!G9)) -> 0.016815735 | G8: =IF(OR(Monthly_Prices_RAW!H10="",Monthly_Prices_RAW!H9=""),"",LN(Monthly_Prices_RAW!H10/Monthly_Prices_RAW!H9)) -> 0.036193001 | H8: =IF(OR(Monthly_Prices_RAW!I10="",Monthly_Prices_RAW!I9=""),"",Monthly_Prices_RAW!I10-Monthly_Prices_RAW!I9)
A9: =Monthly_Prices_RAW!B10 -> 40482 | B9: =IF(OR(Monthly_Prices_RAW!C11="",Monthly_Prices_RAW!C10=""),"",LN(Monthly_Prices_RAW!C11/Monthly_Prices_RAW!C10)) -> -0.01532018 | C9: =IF(OR(Monthly_Prices_RAW!D11="",Monthly_Prices_RAW!D10=""),"",LN(Monthly_Prices_RAW!D11/Monthly_Prices_RAW!D10)) | D9: =IF(OR(Monthly_Prices_RAW!E11="",Monthly_Prices_RAW!E10=""),"",LN(Monthly_Prices_RAW!E11/Monthly_Prices_RAW!E10)) -> 0.023689323 | E9: =IF(OR(Monthly_Prices_RAW!F11="",Monthly_Prices_RAW!F10=""),"",LN(Monthly_Prices_RAW!F11/Monthly_Prices_RAW!F10)) -> -0.029878819 | F9: =IF(OR(Monthly_Prices_RAW!G11="",Monthly_Prices_RAW!G10=""),"",LN(Monthly_Prices_RAW!G11/Monthly_Prices_RAW!G10)) -> -0.025435135 | G9: =IF(OR(Monthly_Prices_RAW!H11="",Monthly_Prices_RAW!H10=""),"",LN(Monthly_Prices_RAW!H11/Monthly_Prices_RAW!H10)) -> -0.0022929095 | H9: =IF(OR(Monthly_Prices_RAW!I11="",Monthly_Prices_RAW!I10=""),"",Monthly_Prices_RAW!I11-Monthly_Prices_RAW!I10)
A10: =Monthly_Prices_RAW!B11 -> 40512 | B10: =IF(OR(Monthly_Prices_RAW!C12="",Monthly_Prices_RAW!C11=""),"",LN(Monthly_Prices_RAW!C12/Monthly_Prices_RAW!C11)) -> 0.11102063 | C10: =IF(OR(Monthly_Prices_RAW!D12="",Monthly_Prices_RAW!D11=""),"",LN(Monthly_Prices_RAW!D12/Monthly_Prices_RAW!D11)) | D10: =IF(OR(Monthly_Prices_RAW!E12="",Monthly_Prices_RAW!E11=""),"",LN(Monthly_Prices_RAW!E12/Monthly_Prices_RAW!E11)) -> 0.15119426 | E10: =IF(OR(Monthly_Prices_RAW!F12="",Monthly_Prices_RAW!F11=""),"",LN(Monthly_Prices_RAW!F12/Monthly_Prices_RAW!F11)) -> 0.082238098 | F10: =IF(OR(Monthly_Prices_RAW!G12="",Monthly_Prices_RAW!G11=""),"",LN(Monthly_Prices_RAW!G12/Monthly_Prices_RAW!G11)) -> 0.065105476 | G10: =IF(OR(Monthly_Prices_RAW!H12="",Monthly_Prices_RAW!H11=""),"",LN(Monthly_Prices_RAW!H12/Monthly_Prices_RAW!H11)) -> 0.063256517 | H10: =IF(OR(Monthly_Prices_RAW!I12="",Monthly_Prices_RAW!I11=""),"",Monthly_Prices_RAW!I12-Monthly_Prices_RAW!I11)
A11: =Monthly_Prices_RAW!B12 -> 40543 | B11: =IF(OR(Monthly_Prices_RAW!C13="",Monthly_Prices_RAW!C12=""),"",LN(Monthly_Prices_RAW!C13/Monthly_Prices_RAW!C12)) -> -0.030893602 | C11: =IF(OR(Monthly_Prices_RAW!D13="",Monthly_Prices_RAW!D12=""),"",LN(Monthly_Prices_RAW!D13/Monthly_Prices_RAW!D12)) | D11: =IF(OR(Monthly_Prices_RAW!E13="",Monthly_Prices_RAW!E12=""),"",LN(Monthly_Prices_RAW!E13/Monthly_Prices_RAW!E12)) -> 0.0025826751 | E11: =IF(OR(Monthly_Prices_RAW!F13="",Monthly_Prices_RAW!F12=""),"",LN(Monthly_Prices_RAW!F13/Monthly_Prices_RAW!F12)) -> 0.020040751 | F11: =IF(OR(Monthly_Prices_RAW!G13="",Monthly_Prices_RAW!G12=""),"",LN(Monthly_Prices_RAW!G13/Monthly_Prices_RAW!G12)) -> -0.025636085 | G11: =IF(OR(Monthly_Prices_RAW!H13="",Monthly_Prices_RAW!H12=""),"",LN(Monthly_Prices_RAW!H13/Monthly_Prices_RAW!H12)) -> 0.022392985 | H11: =IF(OR(Monthly_Prices_RAW!I13="",Monthly_Prices_RAW!I12=""),"",Monthly_Prices_RAW!I13-Monthly_Prices_RAW!I12)
A12: =Monthly_Prices_RAW!B13 -> 40574 | B12: =IF(OR(Monthly_Prices_RAW!C14="",Monthly_Prices_RAW!C13=""),"",LN(Monthly_Prices_RAW!C14/Monthly_Prices_RAW!C13)) -> 0.022767615 | C12: =IF(OR(Monthly_Prices_RAW!D14="",Monthly_Prices_RAW!D13=""),"",LN(Monthly_Prices_RAW!D14/Monthly_Prices_RAW!D13)) | D12: =IF(OR(Monthly_Prices_RAW!E14="",Monthly_Prices_RAW!E13=""),"",LN(Monthly_Prices_RAW!E14/Monthly_Prices_RAW!E13)) -> 0.0043641316 | E12: =IF(OR(Monthly_Prices_RAW!F14="",Monthly_Prices_RAW!F13=""),"",LN(Monthly_Prices_RAW!F14/Monthly_Prices_RAW!F13)) -> 0.031252544 | F12: =IF(OR(Monthly_Prices_RAW!G14="",Monthly_Prices_RAW!G13=""),"",LN(Monthly_Prices_RAW!G14/Monthly_Prices_RAW!G13)) -> 0.021032521 | G12: =IF(OR(Monthly_Prices_RAW!H14="",Monthly_Prices_RAW!H13=""),"",LN(Monthly_Prices_RAW!H14/Monthly_Prices_RAW!H13)) -> 0.031456595 | H12: =IF(OR(Monthly_Prices_RAW!I14="",Monthly_Prices_RAW!I13=""),"",Monthly_Prices_RAW!I14-Monthly_Prices_RAW!I13)
A13: =Monthly_Prices_RAW!B14 -> 40602 | B13: =IF(OR(Monthly_Prices_RAW!C15="",Monthly_Prices_RAW!C14=""),"",LN(Monthly_Prices_RAW!C15/Monthly_Prices_RAW!C14)) -> 0.0095612008 | C13: =IF(OR(Monthly_Prices_RAW!D15="",Monthly_Prices_RAW!D14=""),"",LN(Monthly_Prices_RAW!D15/Monthly_Prices_RAW!D14)) | D13: =IF(OR(Monthly_Prices_RAW!E15="",Monthly_Prices_RAW!E14=""),"",LN(Monthly_Prices_RAW!E15/Monthly_Prices_RAW!E14)) -> -0.038818829 | E13: =IF(OR(Monthly_Prices_RAW!F15="",Monthly_Prices_RAW!F14=""),"",LN(Monthly_Prices_RAW!F15/Monthly_Prices_RAW!F14)) -> 0.018293193 | F13: =IF(OR(Monthly_Prices_RAW!G15="",Monthly_Prices_RAW!G14=""),"",LN(Monthly_Prices_RAW!G15/Monthly_Prices_RAW!G14)) -> 0.013941245 | G13: =IF(OR(Monthly_Prices_RAW!H15="",Monthly_Prices_RAW!H14=""),"",LN(Monthly_Prices_RAW!H15/Monthly_Prices_RAW!H14)) -> -0.0010478507 | H13: =IF(OR(Monthly_Prices_RAW!I15="",Monthly_Prices_RAW!I14=""),"",Monthly_Prices_RAW!I15-Monthly_Prices_RAW!I14)
... A193: =Monthly_Prices_RAW!B194 -> 46081 | B193: =IF(OR(Monthly_Prices_RAW!C195="",Monthly_Prices_RAW!C194=""),"",LN(Monthly_Prices_RAW!C195/Monthly_Prices_RAW!C194)) | C193: =IF(OR(Monthly_Prices_RAW!D195="",Monthly_Prices_RAW!D194=""),"",LN(Monthly_Prices_RAW!D195/Monthly_Prices_RAW!D194)) | D193: =IF(OR(Monthly_Prices_RAW!E195="",Monthly_Prices_RAW!E194=""),"",LN(Monthly_Prices_RAW!E195/Monthly_Prices_RAW!E194)) | E193: =IF(OR(Monthly_Prices_RAW!F195="",Monthly_Prices_RAW!F194=""),"",LN(Monthly_Prices_RAW!F195/Monthly_Prices_RAW!F194)) | F193: =IF(OR(Monthly_Prices_RAW!G195="",Monthly_Prices_RAW!G194=""),"",LN(Monthly_Prices_RAW!G195/Monthly_Prices_RAW!G194)) | G193: =IF(OR(Monthly_Prices_RAW!H195="",Monthly_Prices_RAW!H194=""),"",LN(Monthly_Prices_RAW!H195/Monthly_Prices_RAW!H194)) | H193: =IF(OR(Monthly_Prices_RAW!I195="",Monthly_Prices_RAW!I194=""),"",Monthly_Prices_RAW!I195-Monthly_Prices_RAW!I194)
